Workbook

Sheet Leggimi
A1: Test del Portafoglio e dei pagamenti in app — Canepacce
A2: ASD Tennis Club Monti della Tolfa · App Prenotazioni Canepacce · versione di prova con portafoglio e pagamenti
B4: Cos'è questo file
B5: A cosa serve | C5: L'app ora ha un portafoglio: ogni socio carica del credito (con carta o in contanti al circolo) e quando prenota un campo la sua quota viene scalata in automatico. Questo file elenca tutto quello che va provato prima di accendere la novità per tutti i soci.
B6: Com'è diviso | C6: • "Socio": le prove da fare con un account da socio normale. • "Admin": le prove da fare con un account amministratore. • "Riepilogo": si compila da solo e conta quante prove sono andate bene o male. In fondo a questa pagina c'è la parte "Prima di iniziare" per chi prepara l'ambiente di prova.
B7: Chi lo compila | C7: Prima Tester 1 (Bruno), poi Tester 2 (membro del direttivo). Ognuno ha le sue colonne "Esito" e "Note": non serve cancellare quello che ha scritto l'altro. Scrivi il tuo nome nella riga gialla "Tester 1" / "Tester 2" in alto in ogni scheda.
B9: Come si compila (passo passo)
B10: 1. Leggi la riga | C10: Colonna "Cosa fare (passo passo)": sono le azioni da fare nell'app, in ordine. Colonna "Con quale account": con chi devi essere collegato.
B11: 2. Fai le azioni | C11: Esegui i passi nell'app di prova. Non serve essere veloci e non si rompe nulla: è tutto finto.
B12: 3. Confronta | C12: Colonna "Cosa deve succedere": è il comportamento giusto. Controlla anche le parole e i colori descritti.
B13: 4. Scegli l'esito | C13: Clicca sulla cella "Esito" della tua colonna: compare una freccina con un menu. Scegli: • OK → è successo esattamente quello che c'è scritto • NON OK → è successo qualcosa di diverso (spiega nelle note!) • BLOCCATO → non sei riuscito a fare la prova (es. manca un dato, errore prima di arrivarci) • NON PROVATO → l'hai saltata
B14: 5. Scrivi le note | C14: Nella colonna "Note" scrivi tutto quello che ti ha colpito, anche se l'esito è OK: testi poco chiari, colori che confondono, dubbi, idee. Se qualcosa non va, scrivi cosa hai visto e, se riesci, fai uno screenshot e annota il suo nome nella nota (es. "vedi foto S-27").
B15: Colonna "Già verificata in automatico" | C15: Un "✓ Sì" vuol dire che quella prova la fa già da sola una batteria di test automatici (un browser che clicca al posto nostro e controlla testi e saldi): l'ultimo giro, il 24/09/2026, è andato tutto bene. Su quelle righe basta un'occhiata a come appare la schermata e se i testi sono chiari. Le righe con "—" vanno provate davvero a mano: sono le più importanti.
B16: Consiglio | C16: Segui l'ordine delle righe: alcune prove preparano quelle dopo (es. S-15 serve per S-16). Se una prova dice "PRIMA: …", fai prima quel passaggio.
B18: Carte di prova (nessun addebito reale)
B19: Carta che funziona | C19: 4242 4242 4242 4242 — Scadenza: qualsiasi data futura (es. 12/30) · CVC: 123 · Nome e CAP: a piacere
B20: Carta rifiutata | C20: 4000 0000 0000 0002 — Per il test S-09
B21: Attenzione | C21: Mai inserire una carta vera: l'ambiente di prova non la addebiterebbe comunque, ma non serve.
B23: Account da usare
B24: Mario Prova | C24: socio.prova1@canepacce.test · password: ____________________ · socio con credito
B25: Luigi Prova | C25: socio.prova2@canepacce.test · password: ____________________ · socio che parte senza credito
B26: Admin | C26: il tuo account admin sull'app di prova · email: ____________________
B27: Indirizzo app di prova | C27: ____________________________________________ (te lo dà Bruno)
B29: Parole che incontrerai
B30: Quota | C30: Quello che paga ciascun giocatore per un'ora di campo. La tariffa è "a persona all'ora".
B31: Ora con luci | C31: Un'ora giocata dopo il tramonto costa di più (tariffa "con luci"). L'app lo calcola da sola in base al tramonto del giorno.
B32: Copertura | C32: Se un socio che giochi con te non ha credito, la sua quota la paghi tu. L'app te lo dice PRIMA di confermare, con un riquadro ambra.
B33: Ospite | C33: Un giocatore non socio: la sua quota la paga chi prenota.
B34: Da definire | C34: Un posto riservato a un giocatore che non sai ancora chi sarà: la quota la paga chi prenota, poi puoi sostituirlo con "Modifica".
B35: Colori | C35: Verde = pagato / tutto a posto · Ambra = stai pagando anche per qualcun altro · Rosso = credito insufficiente · Riquadro bianco con "+" = soldi che ti tornano (rimborso).
B37: Prima di iniziare — per chi prepara l'ambiente (Bruno)
B38: 1. Ambiente di prova | C38: Tutti i test si fanno sull'app di PROVA (staging), mai su quella vera. I soldi sono finti: nessuna carta reale viene addebitata.
B39: 2. Pagamenti accesi | C39: Su staging l'impostazione "pagamenti_attivi" deve valere true (SQL Editor: UPDATE app_settings SET value = 'true' WHERE key = 'pagamenti_attivi';). Da spenti non c'è nessun addebito e quasi tutti i test non hanno senso.
B40: 3. Account di prova | C40: Due soci approvati: Mario Prova (socio.prova1@canepacce.test) e Luigi Prova (socio.prova2@canepacce.test), creati da Authentication → Users con "Auto Confirm User". Più un account admin per ciascun tester.
B41: 4. Credito iniziale | C41: Mario: €20 accreditati con "Accredita Contanti" (è anche il test A-03). Luigi: parte da €0.
B42: 5. Tariffa | C42: In "Portafogli Soci" → "Tariffe" deve esserci una tariffa attiva con prezzo di giorno e con luci diversi (es. €3 e €5), così si vede la differenza.
B43: 6. Pagamenti con carta | C43: Le chiavi Stripe di prova e il webhook sono configurati su staging (dal 18/09). Verificare solo che siano ancora attivi e che le funzioni "wallet-create-checkout" e "payment-webhook" siano all'ultima versione.
B44: 7. Due browser | C44: Per alcuni test servono due utenti contemporaneamente: usa un browser normale per uno e una finestra anonima (o un altro browser) per l'altro.

Sheet Socio
A1: Prove con un account da SOCIO
A2: Collegati come socio (Mario o Luigi, vedi colonna "Con quale account"). Segui le righe in ordine. Esito: scegli dal menu nella cella gialla.
G3: Nome tester → | H3: Tester 1: | J3: Tester 2:
A5: ID | B5: Già verificata in automatico | C5: Area | D5: Cosa verifichiamo | E5: Con quale account | F5: Cosa fare (passo passo) | G5: Cosa deve succedere | H5: Esito Tester 1 | I5: Note Tester 1 | J5: Esito Tester 2 | K5: Note Tester 2
A6: 1. IL MIO PORTAFOGLIO
A7: S-01 | B7: ✓ Sì | C7: Portafoglio | D7: Il riquadro del portafoglio è in dashboard | E7: Mario | F7: 1. Accedi con l'account di Mario. 2. Guarda la pagina principale (dashboard). | G7: C'è un riquadro "Il mio Portafoglio", subito dopo "Vista Settimanale", grande come gli altri, con il saldo scritto e un solo bottone "Vai al Portafoglio".
A8: S-02 | B8: ✓ Sì | C8: Portafoglio | D8: Apertura della pagina Portafoglio | E8: Mario | F8: 1. Nel riquadro "Il mio Portafoglio" premi "Vai al Portafoglio". | G8: Si apre la pagina "Il mio Portafoglio" con: saldo disponibile, sezione "Ricarica" con alcuni importi pronti (es. €10, €20, €50) e un campo "Altro importo", elenco "Movimenti recenti". Con la freccia in alto a sinistra torni alla dashboard.
A9: S-03 | B9: — | C9: Portafoglio | D9: Colore del saldo | E9: Mario e Luigi | F9: 1. Guarda il saldo di Mario (che ha credito). 2. Esci, entra come Luigi (saldo €0) e guarda il suo saldo. | G9: Con saldo alto il numero è verde; con saldo basso (sotto circa €5) tende all'arancione. Non è mai rosso.
A10: S-04 | B10: — | C10: Ricarica carta | D10: Ricarica con carta con un importo pronto | E10: Mario | F10: 1. In "Il mio Portafoglio" premi "€10". 2. Si apre la pagina di pagamento: numero carta 4242 4242 4242 4242, scadenza una qualsiasi futura (es. 12/30), CVC 123, nome e CAP a piacere. 3. Paga. | G10: Torni sulla pagina del portafoglio. Compare un avviso giallo "Pagamento in verifica…", che dopo pochi secondi sparisce da solo con il messaggio "Ricarica completata! Saldo aggiornato.". Il saldo è aumentato di €10 e nei movimenti c'è "Ricarica con carta".
A11: S-05 | B11: — | C11: Ricarica carta | D11: Ricarica con importo libero | E11: Mario | F11: 1. Nel campo "Altro importo" scrivi 7,50. 2. Premi "Ricarica" e paga come in S-04. | G11: Saldo aumentato di esattamente €7,50, movimento "Ricarica con carta" in elenco.
A12: S-06 | B12: ✓ Sì | C12: Ricarica carta | D12: Importo non valido | E12: Mario | F12: 1. Nel campo "Altro importo" scrivi 0 e premi "Ricarica". 2. Prova anche con lettere (es. "abc"). | G12: Messaggio "Inserisci un importo valido." e nessuna pagina di pagamento si apre.
A13: S-07 | B13: — | C13: Ricarica carta | D13: Pagamento annullato | E13: Mario | F13: 1. Premi "€10". 2. Nella pagina di pagamento NON pagare: usa la freccia/link per tornare indietro (annulla). | G13: Torni sul portafoglio con il messaggio "Ricarica annullata.". Il saldo NON cambia e non compare nessun movimento nuovo.
A14: S-08 | B14: — | C14: Ricarica carta | D14: Pagamento con pagina chiusa prima del ritorno | E14: Mario | F14: 1. Premi "€10" e paga. 2. Subito dopo aver premuto "Paga", chiudi la scheda del browser senza aspettare il ritorno all'app. 3. Dopo un minuto riapri l'app e vai su "Il mio Portafoglio". | G14: Il saldo è comunque aumentato di €10: l'accredito non dipende dal ritorno sulla pagina.
A15: S-09 | B15: — | C15: Ricarica carta | D15: Carta rifiutata | E15: Mario | F15: 1. Premi "€10". 2. Usa la carta di prova rifiutata 4000 0000 0000 0002. | G15: La pagina di pagamento segnala che la carta è rifiutata. Nell'app il saldo non cambia.
A16: 2. PRENOTARE UN CAMPO
A17: S-10 | B17: ✓ Sì | C17: Prenotazione | D17: Scelta dei partecipanti (ricerca) | E17: Mario | F17: 1. Dashboard → "Prenota un Campo". 2. Scegli data, campo, un orario libero e tipo "Singolare". 3. Nel campo "Cerca o seleziona un socio..." scrivi le prime lettere di "Luigi". | G17: Il tuo nome è già presente come primo partecipante con la scritta "Tu" e senza crocetta (non puoi toglierti). Mentre scrivi, l'elenco si filtra e compare "Luigi Prova". Cliccandolo si aggiunge.
A18: S-11 | B18: ✓ Sì | C18: Prenotazione | D18: Scelta dei partecipanti (sfoglia elenco) | E18: Mario | F18: 1. Come S-10 ma questa volta clicca sul campo di ricerca senza scrivere nulla. | G18: Si apre l'elenco completo dei soci da scorrere. Tu non compari nell'elenco. Un socio già scelto non compare di nuovo.
A19: S-12 | B19: ✓ Sì | C19: Prenotazione | D19: Ospite e "Da definire" | E19: Mario | F19: 1. Scegli tipo "Doppio". 2. Aggiungi Luigi. 3. Premi "Ospite" e scrivi un nome (es. "Paolo Bianchi"). 4. Premi "Da definire". | G19: Compaiono 4 partecipanti: Tu, Luigi, Paolo Bianchi (con scritta "Ospite") e un chip tratteggiato "Da definire". Sotto c'è una riga grigia che spiega la differenza tra Ospite e Da definire. Ogni partecipante tranne te ha la crocetta per toglierlo.
A20: S-13 | B20: ✓ Sì | C20: Prenotazione | D20: Numero di partecipanti per tipo | E20: Mario | F20: 1. Tipo "Singolare": prova a premere "Conferma Prenotazione" con solo te stesso. 2. Tipo "Doppio": prova con solo 2 o 3 partecipanti. | G20: L'app non va avanti e spiega quanti partecipanti servono (singolare = 2, doppio = 4).
A21: S-14 | B21: ✓ Sì | C21: Prenotazione | D21: Lezione con maestro | E21: Mario | F21: 1. Tipo "Lezione", lascia vuoto il nome del maestro e prova a confermare. 2. Poi scrivi un nome maestro e conferma. | G21: Senza nome maestro non si procede. Con il nome si apre il riepilogo. Il maestro non paga in app: pagano solo gli allievi scelti (da 1 a 4).
A22: S-15 | B22: ✓ Sì | C22: Prenotazione | D22: Riepilogo prima di pagare (tutti con credito) | E22: Mario (e Luigi con credito) | F22: PRIMA: fai accreditare €20 anche a Luigi (test A-03 del foglio Admin). 1. Prenota un Singolare di 1 ora con Luigi, in un orario di giorno (es. 10:00). 2. Premi "Conferma Prenotazione" e LEGGI il riepilogo senza confermare. | G22: Si apre "Conferma prenotazione" con: la tua quota (grigio), una riga VERDE "Luigi Prova paga la sua quota" con l'importo, "Totale prenotazione", "Saldo dopo l'operazione". Il bottone dice "Conferma e paga €X" con la TUA quota, non un generico "Conferma".
A23: S-16 | B23: ✓ Sì | C23: Prenotazione | D23: Conferma e riepilogo finale | E23: Mario | F23: 1. Dal riepilogo di S-15 premi "Conferma e paga €X". | G23: Popup "Prenotazione Confermata!" con campo, data, orario e un "Riepilogo pagamenti" con segni di spunta verdi: "Hai pagato la tua quota" e "Luigi Prova ha pagato la sua quota". Nel portafoglio di Mario e in quello di Luigi compare l'addebito "Prenotazione campo".
A24: S-17 | B24: ✓ Sì | C24: Prenotazione | D24: Un partecipante senza credito (copertura) | E24: Mario + Luigi a €0 | F24: PRIMA: Luigi deve avere saldo €0 (se serve, fagli togliere il credito con il test A-04). 1. Mario prenota un Singolare con Luigi. 2. Leggi il riepilogo. | G24: Compare un riquadro AMBRA: "Luigi Prova non ha credito sufficiente → i €X verranno scalati dal TUO saldo". Il bottone mostra la tua quota + quella di Luigi. Dopo la conferma: "Hai coperto tu la quota di Luigi Prova". Il saldo di Luigi NON viene toccato.
A25: S-18 | B25: ✓ Sì | C25: Prenotazione | D25: Ospite pagato dal prenotante | E25: Mario | F25: 1. Prenota un Doppio con Luigi (con credito), un Ospite e un "Da definire". 2. Leggi il riepilogo. | G25: La "Tua quota" comprende anche la quota dell'ospite e del "Da definire" (c'è scritto "comprende eventuali ospiti"). Luigi paga solo la sua.
A26: S-19 | B26: ✓ Sì | C26: Prenotazione | D26: Saldo insufficiente: dettaglio | E26: Luigi a €0 | F26: 1. Entra come Luigi (saldo €0). 2. Prenota un Singolare con Mario e premi "Conferma Prenotazione". | G26: Riquadro ROSSO "Saldo insufficiente per Luigi Prova" con le righe di dettaglio (quota propria ed eventuali quote coperte), "Servono in totale", "Disponibili" e "Ti mancano €X". Il bottone di conferma è disattivato. Nessun addebito a nessuno.
A27: S-20 | B27: ✓ Sì | C27: Prenotazione | D27: Saldo insufficiente: bottone Ricarica | E27: Luigi a €0 | F27: 1. Dal riquadro rosso di S-19 premi "Ricarica €X". | G27: Si apre "Il mio Portafoglio" con l'importo mancante già scritto in "Altro importo" (lo puoi cambiare). Sotto il bottone c'era anche la riga "Puoi anche ricaricare in contanti presso il circolo."
A28: S-21 | B28: ✓ Sì | C28: Prenotazione | D28: Ritorno alla prenotazione dopo la ricarica | E28: Luigi | F28: 1. Da S-20 paga la ricarica con la carta 4242…. 2. Aspetta che l'avviso giallo sparisca. | G28: Compare un riquadro verde "Hai una prenotazione da completare…" con "Torna a prenotare" (riporta a "Prenota un Campo") e "Non ora" (chiude l'avviso). Campo e orario vanno scelti di nuovo: è normale.
... A32: S-25 | B32: ✓ Sì | C32: Regole invariate | D32: Limiti di prenotazione come prima | E32: Mario | F32: 1. Prova a prenotare più di 2 ore di fila. 2. Prova a prenotare oltre 14 giorni da oggi. 3. Fai 2 prenotazioni nella stessa settimana e prova la terza. | G32: Tutti i limiti funzionano come prima dei pagamenti (max 2 ore, max 14 giorni, max 2 prenotazioni a settimana) e nessun addebito avviene per un tentativo bloccato.
A33: 3. I MIEI CAMPI: MODIFICA E DISDETTA
A34: S-26 | B34: ✓ Sì | C34: Modifica | D34: Allungare una prenotazione (paghi) | E34: Mario | F34: 1. Dashboard → "I miei Campi" → su una prenotazione di 1 ora premi "Modifica". 2. Aggiungi un'ora consecutiva e premi "Salva Modifiche". | G34: Si apre "Conferma modifica". Compaiono solo gli addebiti per l'ora in più. Il bottone dice "Conferma e paga €X". Dopo la conferma il saldo scende solo dell'ora aggiunta.
A35: S-27 | B35: ✓ Sì | C35: Modifica | D35: Accorciare una prenotazione (ricevi un rimborso) | E35: Mario | F35: 1. Su una prenotazione di 2 ore premi "Modifica". 2. Togli un'ora e premi "Salva Modifiche". | G35: Titolo "Conferma modifica". In alto: "Con questa modifica non paghi nulla: ricevi un rimborso sul tuo saldo". Sezione "Rimborsi" con righe bianche bordate e importo col "+" (es. "+€3,00"). Bottone "Conferma e ricevi €X". Dopo la conferma: "Prenotazione aggiornata: €X rimborsati sul tuo saldo." NIENTE deve far pensare che stai pagando di nuovo.
A36: S-28 | B36: ✓ Sì | C36: Modifica | D36: Sostituire un partecipante | E36: Mario | F36: 1. Su un Doppio con partecipanti soci premi "Modifica". 2. Togli un socio e metti un altro socio. | G36: Nel riepilogo: rimborso al socio che esce e addebito a quello che entra. Se per te non cambia nulla il bottone dice "Conferma modifica".
A37: S-29 | B37: ✓ Sì | C37: Modifica | D37: Modifica che non cambia il costo | E37: Mario | F37: 1. Su un Doppio sostituisci un "Da definire" con un ospite. | G37: Riepilogo con la scritta "Il costo non cambia: nessun addebito e nessun rimborso."
A38: S-30 | B38: ✓ Sì | C38: Modifica | D38: Quota coperta che torna indietro | E38: Mario + Luigi a €0 | F38: 1. Usa la prenotazione di S-17 (dove Mario ha coperto Luigi). 2. Modificala togliendo Luigi e mettendo un altro partecipante. | G38: Nella sezione "Rimborsi" compare "Ti torna la quota che avevi coperto per Luigi Prova" con importo "+€X".
A39: S-31 | B39: ✓ Sì | C39: Disdetta | D39: Eliminare una prenotazione pagata | E39: Mario | F39: 1. In "I miei Campi" premi il cestino su una prenotazione pagata. 2. Leggi la finestra, poi conferma con "Elimina". | G39: Prima di confermare: riga "Ti verranno rimborsati sul saldo +€X" e frase grigia "Chi ha pagato la propria quota dal portafoglio la riceve indietro per intero." Dopo: "Prenotazione annullata. €X rimborsati sul tuo saldo." (più "Anche gli altri partecipanti sono stati rimborsati." se c'erano altri soci).
A40: S-32 | B40: ✓ Sì | C40: Disdetta | D40: Rimborso anche agli altri partecipanti | E40: Luigi | F40: 1. Dopo S-31, entra come Luigi (se era nella prenotazione). 2. Apri "Il mio Portafoglio". | G40: Nei movimenti di Luigi c'è il rimborso della sua quota e il saldo è tornato come prima della prenotazione.
A41: S-33 | B41: — | C41: Disdetta | D41: Troppo tardi per modificare o disdire | E41: Mario | F41: 1. Prenota uno slot che inizia a breve (l'ora in corso o la prossima). 2. Dopo l'orario di inizio prova a modificarlo o eliminarlo. | G41: Non si riesce: o i bottoni "Modifica"/cestino non ci sono più, o compare un messaggio chiaro (modifica e disdetta sono consentite fino a 1 minuto prima dell'inizio). Nessun movimento di soldi.
A42: 4. PRENOTA PER SOCIO (CONTO TERZI)
A43: S-34 | B43: ✓ Sì | C43: Conto terzi | D43: Prenotare per altri senza giocare | E43: Mario | F43: 1. Dashboard → "Prenota per Socio". 2. Scegli campo e orario, aggiungi come partecipanti Luigi e un altro socio (o ospite). 3. Conferma. | G43: Tu NON compari tra i partecipanti. Il primo socio scelto è quello "per cui" è la prenotazione. Nel riepilogo ciascun socio paga la propria quota; se qualcuno non ha credito la sua quota passa a te (riquadro ambra).
A44: S-35 | B44: ✓ Sì | C44: Conto terzi | D44: Limite di 1 prenotazione per terzi a settimana | E44: Mario | F44: 1. Dopo S-34 prova a fare una seconda prenotazione per terzi nella stessa settimana. | G44: L'app lo blocca con un messaggio chiaro (max 1 per settimana). Nessun addebito.
...

Sheet Admin
A1: Prove con un account AMMINISTRATORE
A2: Collegati come admin. Alcune prove chiedono di controllare poi con Mario o Luigi. Esito: scegli dal menu nella cella gialla.
G3: Nome tester → | H3: Tester 1: | J3: Tester 2:
A5: ID | B5: Già verificata in automatico | C5: Area | D5: Cosa verifichiamo | E5: Con quale account | F5: Cosa fare (passo passo) | G5: Cosa deve succedere | H5: Esito Tester 1 | I5: Note Tester 1 | J5: Esito Tester 2 | K5: Note Tester 2
A6: 1. PORTAFOGLI SOCI: TAB SOCI
A7: A-01 | B7: — | C7: Portafogli soci | D7: Il riquadro è nel pannello admin | E7: Admin | F7: 1. Accedi come admin → "Pannello Admin". | G7: C'è il riquadro "Portafogli Soci". Aprendolo si vedono tre schede: "Soci", "Tariffe", "Luci".
A8: A-02 | B8: ✓ Sì | C8: Portafogli soci | D8: Cercare un socio e vederne il saldo | E8: Admin | F8: 1. Scheda "Soci" → in "Cerca Socio" scrivi "Mario". 2. Clicca su "Mario Prova". | G8: Compaiono il saldo di Mario, i bottoni "Accredita Contanti" e "Correggi Saldo" e lo storico completo dei suoi movimenti (uguale a quello che vede Mario).
A9: A-03 | B9: ✓ Sì | C9: Contanti | D9: Accreditare contanti | E9: Admin | F9: 1. Seleziona Luigi → "Accredita Contanti". 2. Importo 20, nota "Contanti ricevuti per test". 3. Conferma. | G9: Saldo di Luigi +€20. Nello storico: "Ricarica in contanti" con la nota. Entrando come Luigi, vede lo stesso movimento nel suo portafoglio.
A10: A-04 | B10: ✓ Sì | C10: Correzione | D10: Togliere credito con Correggi Saldo | E10: Admin | F10: 1. Seleziona Luigi → "Correggi Saldo" → "Rimuovi credito". 2. Importo 5, motivo "Test correzione". 3. Conferma. | G10: Saldo di Luigi −€5, movimento di correzione con il motivo, visibile anche a Luigi.
A11: A-05 | B11: ✓ Sì | C11: Correzione | D11: Aggiungere credito con Correggi Saldo | E11: Admin | F11: 1. Come A-04 ma con "Aggiungi credito" di €5. | G11: Saldo di Luigi +€5, movimento di correzione con il motivo.
A12: A-06 | B12: ✓ Sì | C12: Correzione | D12: Nota obbligatoria | E12: Admin | F12: 1. Apri "Accredita Contanti" o "Correggi Saldo", metti un importo e lascia vuota la nota/motivo. 2. Conferma. | G12: L'app non procede e chiede di indicare la nota. Nessun movimento.
A13: A-07 | B13: ✓ Sì | C13: Correzione | D13: Il saldo non va mai sotto zero | E13: Admin | F13: 1. Luigi con pochi euro: prova "Correggi Saldo" → "Rimuovi credito" di un importo più alto del suo saldo. | G13: Operazione rifiutata con un messaggio chiaro. Saldo invariato.
A14: 2. TARIFFE
A15: A-08 | B15: — | C15: Tariffe | D15: Vedere la tariffa attuale | E15: Admin | F15: 1. "Portafogli Soci" → scheda "Tariffe". | G15: In evidenza la tariffa in vigore (€ a persona all'ora di giorno e con luci) e sotto lo storico delle tariffe.
A16: A-09 | B16: — | C16: Tariffe | D16: Nuova tariffa da adesso | E16: Admin | F16: 1. Compila "€ / persona / ora" (es. 4,00) e "€ con luci" (es. 6,00), nota facoltativa. 2. Decorrenza: adesso. Salva. 3. Da Mario apri il riepilogo di una nuova prenotazione (senza confermare). | G16: La nuova tariffa appare come attuale e la vecchia resta nello storico. Il riepilogo di Mario usa i nuovi prezzi.
A17: A-10 | B17: — | C17: Tariffe | D17: Le prenotazioni già fatte conservano il prezzo | E17: Admin + Mario | F17: 1. Prima di A-09 Mario deve avere una prenotazione futura pagata con la tariffa vecchia. 2. Dopo A-09 controlla quella prenotazione. | G17: La prenotazione vecchia non viene riaddebitata: resta al prezzo pagato. (Se Mario la allunga, solo l'ora nuova usa la tariffa nuova.)
A18: A-11 | B18: ✓ Sì | C18: Tariffe | D18: Nessuna tariffa nel passato | E18: Admin | F18: 1. Prova a creare una tariffa con decorrenza in una data passata. | G18: Operazione rifiutata con un messaggio chiaro.
A19: A-12 | B19: — | C19: Tariffe | D19: Rimettere la tariffa corretta | E19: Admin | F19: 1. A fine test crea di nuovo una tariffa con i prezzi reali decisi dal circolo. | G19: La tariffa attuale è quella giusta per le prove successive.
A20: 3. LUCI
A21: A-13 | B21: — | C21: Luci | D21: Cambiare il margine dopo il tramonto | E21: Admin | F21: 1. "Portafogli Soci" → scheda "Luci". 2. Cambia "Margine di tolleranza (minuti dopo il tramonto)" (es. da 30 a 60) e premi "Salva". 3. Da Mario apri il riepilogo di un'ora vicina al tramonto. | G21: Il valore resta salvato. Con un margine più alto, un'ora che prima era "con luci" può diventare di giorno. Alla fine rimetti il valore originale.
A22: A-14 | B22: ✓ Sì | C22: Luci | D22: "Sempre luci" per un giorno | E22: Admin + Mario | F22: 1. Scegli una data, seleziona "Sempre luci", motivo "Test" → "Salva Override". 2. Da Mario apri il riepilogo di un'ora a mezzogiorno di quella data. | G22: L'override compare in elenco. Il riepilogo di Mario mostra quell'ora "con luci" e il prezzo luci.
A23: A-15 | B23: — | C23: Luci | D23: "Mai luci" per un giorno | E23: Admin + Mario | F23: 1. Come A-14 ma con "Mai luci" su un'altra data. 2. Da Mario apri il riepilogo di un'ora serale (es. 21:00) di quella data. | G23: L'ora serale risulta di giorno (prezzo senza luci).
A24: A-16 | B24: ✓ Sì | C24: Luci | D24: Rimuovere un override | E24: Admin | F24: 1. Nell'elenco degli override rimuovine uno e conferma in "Rimuovi override luci". | G24: L'override sparisce e quella data torna al calcolo automatico.
A25: 4. PANNELLO PRENOTAZIONI
A26: A-17 | B26: ✓ Sì | C26: Prenotazioni admin | D26: Prenotare per soci che pagano in contanti | E26: Admin | F26: 1. "Pannello Admin" → "Prenotazioni". 2. Clicca uno slot libero (il "+"), scrivi nome e cognome, durata, "Crea". | G26: La prenotazione appare nella griglia. NESSUN portafoglio viene toccato (né quello dell'admin né altri).
A27: A-18 | B27: ✓ Sì | C27: Prenotazioni admin | D27: Segnare i contanti incassati | E27: Admin | F27: 1. Sullo slot creato in A-17 clicca l'icona "€" in alto a destra. 2. Ricliccala. | G27: Primo clic: icona verde, slot verde, "Ora segnata come pagata.", il riepilogo in alto conta l'ora tra le "pagate". Secondo clic: torna "da pagare".
A28: A-19 | B28: ✓ Sì | C28: Prenotazioni admin | D28: Ore pagate col portafoglio | E28: Admin | F28: 1. Trova nella griglia l'ora prenotata e pagata da Mario in app. 2. Passa sopra l'icona in alto a destra e prova a cliccarla. 3. Apri il dettaglio (icona occhio). | G28: Al posto della "€" c'è un'icona portafoglio verde fissa, non cliccabile ("Pagata col portafoglio in app"). Lo slot è verde e contato tra le "pagate". Il dettaglio dice "Pagata col portafoglio in app".
A29: A-20 | B29: ✓ Sì | C29: Prenotazioni admin | D29: Annullare una prenotazione pagata in app | E29: Admin + Mario | F29: 1. Sull'ora pagata da Mario premi il cestino. 2. Leggi la finestra e conferma "Sì, elimina". 3. Entra come Mario e guarda il portafoglio. | G29: La finestra dice "Chi ha pagato quest'ora dal portafoglio verrà rimborsato." Dopo: "Prenotazione annullata. Chi aveva pagato è stato rimborsato sul portafoglio." Mario (e gli altri che avevano pagato) ricevono il rimborso nei movimenti.
A30: A-21 | B30: ✓ Sì | C30: Prenotazioni admin | D30: Annullare una sola ora di una prenotazione da 2 | E30: Admin | F30: 1. Su una prenotazione da 2 ore pagata in app elimina solo una delle due ore. | G30: Viene rimborsata solo l'ora eliminata; l'altra resta valida e pagata.
A31: A-22 | B31: ✓ Sì | C31: Prenotazioni admin | D31: Annullare una prenotazione creata dal pannello | E31: Admin | F31: 1. Elimina lo slot creato in A-17. | G31: Messaggio "Prenotazione annullata." e nessun movimento su nessun portafoglio.
A32: A-23 | B32: ✓ Sì | C32: Prenotazioni admin | D32: Spostare l'orario di una prenotazione pagata | E32: Admin | F32: 1. Su un'ora pagata in app premi "Modifica" (matita), cambia orario e "Salva". | G32: L'orario cambia. I saldi NON cambiano (regola decisa: resta il prezzo pagato; eventuali differenze giorno/luci si sistemano a mano con "Correggi Saldo").
A33: A-24 | B33: — | C33: Prenotazioni admin | D33: Blocca Slot e Scuola Tennis non toccano i soldi | E33: Admin | F33: 1. Blocca uno slot da "Blocca Slot". 2. Crea una prenotazione da "Prenotazione Scuola Tennis". | G33: Funzionano come prima. Nessun movimento su nessun portafoglio.
A34: A-25 | B34: ✓ Sì | C34: Prenotazioni admin | D34: L'admin che prenota dall'app paga come tutti | E34: Admin | F34: 1. Dall'area socio ("Prenota un Campo") l'admin prenota per sé con un altro socio. | G34: Riepilogo e addebiti come per qualsiasi socio (l'admin resta esente dai limiti settimanali/durata, ma paga la quota).
A35: 5. ANAGRAFICA SOCI
A36: A-26 | B36: ✓ Sì | C36: Anagrafica | D36: Eliminare un socio con portafoglio | E36: Admin | F36: 1. "Anagrafica Soci" → prova a eliminare Mario (ha movimenti). | G36: Messaggio chiaro: "Non è possibile eliminare questo socio: ha un portafoglio con movimenti o prenotazioni collegate. Puoi revocargli l'accesso invece di eliminarlo." Nessun errore tecnico in inglese.
A37: A-27 | B37: ✓ Sì | C37: Anagrafica | D37: Revocare l'accesso invece di eliminare | E37: Admin | F37: 1. Su Mario usa l'interruttore di approvazione per revocargli l'accesso. 2. Poi riabilitalo. | G37: Il saldo e i movimenti di Mario restano intatti in entrambi i passaggi.
A38: 6. CONTROLLI DI COERENZA
A39: A-28 | B39: ✓ Sì | C39: Coerenza | D39: I conti tornano | E39: Admin | F39: 1. A fine giornata di test, per Mario e Luigi confronta in "Portafogli Soci" il saldo con la somma dei movimenti in elenco. | G39: Saldo = somma di ricariche + contanti + correzioni − addebiti + rimborsi. Nessuna differenza.
A40: A-29 | B40: ✓ Sì | C40: Coerenza | D40: Pagamenti spenti | E40: Solo Bruno | F40: 1. (Da fare solo con Bruno) si spegne il pagamento in app dall'impostazione "pagamenti_attivi". 2. Mario prenota. | G40: Riepilogo "Nessun addebito: i pagamenti in app non sono ancora attivi." e bottone "Conferma prenotazione". Nessun movimento. Poi si riaccende.

Sheet Riepilogo
A1: Riepilogo esiti (si aggiorna da solo)
B3: Tester 1
B4: Scheda | C4: Prove totali | D4: OK | E4: NON OK | F4: BLOCCATO | G4: NON PROVATO | H4: Da fare
B5: Socio | C5: =COUNTIF('Socio'!A6:A51,"?-??") -> 40 | D5: =COUNTIF('Socio'!H6:H51,"OK") | E5: =COUNTIF('Socio'!H6:H51,"NON OK") | F5: =COUNTIF('Socio'!H6:H51,"BLOCCATO") | G5: =COUNTIF('Socio'!H6:H51,"NON PROVATO") | H5: =C5-SUM(D5:G5)
B6: Admin | C6: =COUNTIF('Admin'!A6:A40,"?-??") -> 29 | D6: =COUNTIF('Admin'!H6:H40,"OK") | E6: =COUNTIF('Admin'!H6:H40,"NON OK") | F6: =COUNTIF('Admin'!H6:H40,"BLOCCATO") | G6: =COUNTIF('Admin'!H6:H40,"NON PROVATO") | H6: =C6-SUM(D6:G6)
B7: Totale | C7: =SUM(C5:C6) | D7: =SUM(D5:D6) | E7: =SUM(E5:E6) | F7: =SUM(F5:F6) | G7: =SUM(G5:G6) | H7: =SUM(H5:H6)
B10: Tester 2
B11: Scheda | C11: Prove totali | D11: OK | E11: NON OK | F11: BLOCCATO | G11: NON PROVATO | H11: Da fare
B12: Socio | C12: =COUNTIF('Socio'!A6:A51,"?-??") -> 40 | D12: =COUNTIF('Socio'!J6:J51,"OK") | E12: =COUNTIF('Socio'!J6:J51,"NON OK") | F12: =COUNTIF('Socio'!J6:J51,"BLOCCATO") | G12: =COUNTIF('Socio'!J6:J51,"NON PROVATO") | H12: =C12-SUM(D12:G12)
B13: Admin | C13: =COUNTIF('Admin'!A6:A40,"?-??") -> 29 | D13: =COUNTIF('Admin'!J6:J40,"OK") | E13: =COUNTIF('Admin'!J6:J40,"NON OK") | F13: =COUNTIF('Admin'!J6:J40,"BLOCCATO") | G13: =COUNTIF('Admin'!J6:J40,"NON PROVATO") | H13: =C13-SUM(D13:G13)
B14: Totale | C14: =SUM(C12:C13) | D14: =SUM(D12:D13) | E14: =SUM(E12:E13) | F14: =SUM(F12:F13) | G14: =SUM(G12:G13) | H14: =SUM(H12:H13)
B17: Le prove con esito NON OK si trovano velocemente: nella scheda Socio o Admin usa la freccina del filtro sull'intestazione "Esito" e lascia spuntato solo "NON OK".
